<?xml version="1.0"?>
<robot name="onrobot_2fg7" xmlns:xacro="http://www.ros.org/wiki/xacro">
    <!-- Base Link -->
    <link name="2fg7_base_link">
        <visual>
            <origin xyz="0 0 0" rpy="0 0 0"/>
            <geometry>
                <mesh filename="package://onrobot_2fg7/meshes/base_link.stl" scale="0.001 0.001 0.001"/>
            </geometry>
            <material name="gray">
                <color rgba="0.2 0.2 0.2 1.0"/>
            </material>
        </visual>
    </link>

    <!-- Right Finger Link -->
    <link name="2fg7_rightfinger">
        <visual>
            <origin xyz="0 0 0" rpy="0 0 0"/>
            <geometry>
                <mesh filename="package://onrobot_2fg7/meshes/right_finger_link.stl" scale="0.001 0.001 0.001"/>
            </geometry>
            <material name="silver">
                <color rgba="0.8 0.8 0.8 1"/>
            </material>
        </visual>
    </link>

    <!-- Right Finger Joint -->
    <joint name="2fg7_rightfinger_joint" type="prismatic">
        <parent link="2fg7_base_link"/>
        <child link="2fg7_rightfinger"/>
        <origin xyz="0 0 0" rpy="0 0 0"/>
        <axis xyz="1 0 0"/>
        <limit lower="0" upper="0.019" effort="140" velocity="0.45"/>
    </joint>

    <!-- Left Finger Link -->
    <link name="2fg7_leftfinger">
        <visual>
            <origin xyz="0 0 0" rpy="0 0 0"/>
            <geometry>
                <mesh filename="package://onrobot_2fg7/meshes/left_finger_link.stl" scale="0.001 0.001 0.001"/>
            </geometry>
            <material name="silver">
                <color rgba="0.8 0.8 0.8 1"/>
            </material>
        </visual>
    </link>

    <!-- Left Finger Joint -->
    <joint name="2fg7_leftfinger_joint" type="prismatic">
        <parent link="2fg7_base_link"/>
        <child link="2fg7_leftfinger"/>
        <origin xyz="0 0 0" rpy="0 0 0"/>
        <axis xyz="-1 0 0"/>
        <limit lower="0" upper="0.019" effort="140" velocity="0.45"/>
    </joint>

    <!-- Transmissions remain the same -->
    <transmission name="2fg7_right_trans">
        <type>transmission_interface/SimpleTransmission</type>
        <joint name="2fg7_rightfinger_joint">
            <hardwareInterface>hardware_interface/PositionJointInterface</hardwareInterface>
        </joint>
        <actuator name="2fg7_right_motor">
            <hardwareInterface>hardware_interface/PositionJointInterface</hardwareInterface>
            <mechanicalReduction>1</mechanicalReduction>
        </actuator>
    </transmission>

    <transmission name="2fg7_left_trans">
        <type>transmission_interface/SimpleTransmission</type>
        <joint name="2fg7_leftfinger_joint">
            <hardwareInterface>hardware_interface/PositionJointInterface</hardwareInterface>
        </joint>
        <actuator name="2fg7_left_motor">
            <hardwareInterface>hardware_interface/PositionJointInterface</hardwareInterface>
            <mechanicalReduction>1</mechanicalReduction>
        </actuator>
    </transmission>
</robot>